Workbook
Name DENAH: #REF!
Name DENAH_MSKU: #REF!
Name DENAH_NAMA: #REF!
Name DENAH_RAK: #REF!
Name DENAH_QTY: #REF!

Sheet Jadwal
A1: No. | B1: Nama Unit | C1: Kode SKU | D1: Tanggal Order | E1: Estimasi Datang | F1: Qty | G1: Harga Beli | H1: Status | I1: Keterangan
A2: =IF(B2<>"",ROW(B2)-ROW($B$1),"") -> 1 | B2: PH METER | C2: {=IFS(B2="","",COUNTIF('Master Barang'!B:B,B2)=0,SUBSTITUTE(TRIM(B2)," ","-"),COUNTIF('Master Barang'!B:B,B2)=1,XLOOKUP(B2,'Master Barang'!B:B,'Master Barang'!C:C,,,1))} -> 009B/PHMETER | D2: 45748 | E2: 45752 | F2: 20 | G2: 150000 | H2: Closed | I2: =IFERROR(__xludf.DUMMYFUNCTION("if(OR(B2="""",E2=""""),"""", LET( Nama, B2, SKU, C2, Estimasi, E2, QtyOrder, F2, FilterTrans, FILTER( Transaksi!B:H, Transaksi!F:F=""Barang Datang"", Transaksi!D:D=Nama, Transaksi!E:E=SKU ), TotalDatang, IFERROR(SUM(IND"&"EX(FilterTrans,,7)), 0), TanggalDatang, IFERROR(MAX(INDEX(FilterTrans,,1)), 0), SelisihQty, QtyOrder-TotalDatang, SelisihHari, TanggalDatang-Estimasi, KeteranganQty, IF(SelisihQty=0, ""Oke"", IF(SelisihQty>0, ""Kurang "" & SelisihQty & "&""" pcs"", ""Lebih "" & ABS(SelisihQty) & "" pcs"")), KeteranganHari, IF(TanggalDatang=0, ""Belum datang"", IF(SelisihHari=0, """", IF(SelisihHari>0, ""Terlambat "" & SelisihHari & "" hari"", ""Lebih cepat "" & ABS(SelisihHari) & """&" hari""))), Hasil, IF(TanggalDatang=0, KeteranganHari, IF(AND(SelisihQty=0, SelisihHari=0), ""Oke"", IF(SelisihQty=0, KeteranganHari, IF(SelisihHari=0, KeteranganQty, KeteranganHari & "" dengan "" & LOWER(KeteranganQty))))), Hasi"&"l ))"),"Oke") -> Oke
A3: =IF(B3<>"",ROW(B3)-ROW($B$1),"") -> 2 | B3: VALVE | C3: {=IFS(B3="","",COUNTIF('Master Barang'!B:B,B3)=0,SUBSTITUTE(TRIM(B3)," ","-"),COUNTIF('Master Barang'!B:B,B3)=1,XLOOKUP(B3,'Master Barang'!B:B,'Master Barang'!C:C,,,1))} -> 512-FITTING-VALVE | D3: 45749 | E3: 45754 | F3: 50 | G3: 35000 | H3: Open | I3: =IFERROR(__xludf.DUMMYFUNCTION("if(OR(B3="""",E3=""""),"""", LET( Nama, B3, SKU, C3, Estimasi, E3, QtyOrder, F3, FilterTrans, FILTER( Transaksi!B:H, Transaksi!F:F=""Barang Datang"", Transaksi!D:D=Nama, Transaksi!E:E=SKU ), TotalDatang, IFERROR(SUM(IND"&"EX(FilterTrans,,7)), 0), TanggalDatang, IFERROR(MAX(INDEX(FilterTrans,,1)), 0), SelisihQty, QtyOrder-TotalDatang, SelisihHari, TanggalDatang-Estimasi, KeteranganQty, IF(SelisihQty=0, ""Oke"", IF(SelisihQty>0, ""Kurang "" & SelisihQty & "&""" pcs"", ""Lebih "" & ABS(SelisihQty) & "" pcs"")), KeteranganHari, IF(TanggalDatang=0, ""Belum datang"", IF(SelisihHari=0, """", IF(SelisihHari>0, ""Terlambat "" & SelisihHari & "" hari"", ""Lebih cepat "" & ABS(SelisihHari) & """&" hari""))), Hasil, IF(TanggalDatang=0, KeteranganHari, IF(AND(SelisihQty=0, SelisihHari=0), ""Oke"", IF(SelisihQty=0, KeteranganHari, IF(SelisihHari=0, KeteranganQty, KeteranganHari & "" dengan "" & LOWER(KeteranganQty))))), Hasi"&"l ))"),"Belum datang") -> Belum datang
A4: =IF(B4<>"",ROW(B4)-ROW($B$1),"") -> 3 | B4: TIES 10 HITAM | C4: {=IFS(B4="","",COUNTIF('Master Barang'!B:B,B4)=0,SUBSTITUTE(TRIM(B4)," ","-"),COUNTIF('Master Barang'!B:B,B4)=1,XLOOKUP(B4,'Master Barang'!B:B,'Master Barang'!C:C,,,1))} -> 001C/TIES-10-HITAM | D4: 45750 | E4: 45755 | F4: 100 | G4: 18000 | H4: Open | I4: =IFERROR(__xludf.DUMMYFUNCTION("if(OR(B4="""",E4=""""),"""", LET( Nama, B4, SKU, C4, Estimasi, E4, QtyOrder, F4, FilterTrans, FILTER( Transaksi!B:H, Transaksi!F:F=""Barang Datang"", Transaksi!D:D=Nama, Transaksi!E:E=SKU ), TotalDatang, IFERROR(SUM(IND"&"EX(FilterTrans,,7)), 0), TanggalDatang, IFERROR(MAX(INDEX(FilterTrans,,1)), 0), SelisihQty, QtyOrder-TotalDatang, SelisihHari, TanggalDatang-Estimasi, KeteranganQty, IF(SelisihQty=0, ""Oke"", IF(SelisihQty>0, ""Kurang "" & SelisihQty & "&""" pcs"", ""Lebih "" & ABS(SelisihQty) & "" pcs"")), KeteranganHari, IF(TanggalDatang=0, ""Belum datang"", IF(SelisihHari=0, """", IF(SelisihHari>0, ""Terlambat "" & SelisihHari & "" hari"", ""Lebih cepat "" & ABS(SelisihHari) & """&" hari""))), Hasil, IF(TanggalDatang=0, KeteranganHari, IF(AND(SelisihQty=0, SelisihHari=0), ""Oke"", IF(SelisihQty=0, KeteranganHari, IF(SelisihHari=0, KeteranganQty, KeteranganHari & "" dengan "" & LOWER(KeteranganQty))))), Hasi"&"l ))"),"Belum datang") -> Belum datang
A5: =IF(B5<>"",ROW(B5)-ROW($B$1),"") -> 4 | B5: SIGMAT | C5: {=IFS(B5="","",COUNTIF('Master Barang'!B:B,B5)=0,SUBSTITUTE(TRIM(B5)," ","-"),COUNTIF('Master Barang'!B:B,B5)=1,XLOOKUP(B5,'Master Barang'!B:B,'Master Barang'!C:C,,,1))} -> 014B/SIGMAT | D5: 45752 | E5: 45757 | F5: 30 | G5: 25000 | H5: Open | I5: =IFERROR(__xludf.DUMMYFUNCTION("if(OR(B5="""",E5=""""),"""", LET( Nama, B5, SKU, C5, Estimasi, E5, QtyOrder, F5, FilterTrans, FILTER( Transaksi!B:H, Transaksi!F:F=""Barang Datang"", Transaksi!D:D=Nama, Transaksi!E:E=SKU ), TotalDatang, IFERROR(SUM(IND"&"EX(FilterTrans,,7)), 0), TanggalDatang, IFERROR(MAX(INDEX(FilterTrans,,1)), 0), SelisihQty, QtyOrder-TotalDatang, SelisihHari, TanggalDatang-Estimasi, KeteranganQty, IF(SelisihQty=0, ""Oke"", IF(SelisihQty>0, ""Kurang "" & SelisihQty & "&""" pcs"", ""Lebih "" & ABS(SelisihQty) & "" pcs"")), KeteranganHari, IF(TanggalDatang=0, ""Belum datang"", IF(SelisihHari=0, """", IF(SelisihHari>0, ""Terlambat "" & SelisihHari & "" hari"", ""Lebih cepat "" & ABS(SelisihHari) & """&" hari""))), Hasil, IF(TanggalDatang=0, KeteranganHari, IF(AND(SelisihQty=0, SelisihHari=0), ""Oke"", IF(SelisihQty=0, KeteranganHari, IF(SelisihHari=0, KeteranganQty, KeteranganHari & "" dengan "" & LOWER(KeteranganQty))))), Hasi"&"l ))"),"Belum datang") -> Belum datang
A6: =IF(B6<>"",ROW(B6)-ROW($B$1),"") -> 5 | B6: KENI | C6: {=IFS(B6="","",COUNTIF('Master Barang'!B:B,B6)=0,SUBSTITUTE(TRIM(B6)," ","-"),COUNTIF('Master Barang'!B:B,B6)=1,XLOOKUP(B6,'Master Barang'!B:B,'Master Barang'!C:C,,,1))} -> 510-FITTING-KENI | D6: 45754 | E6: 45759 | F6: 75 | G6: 30000 | H6: Open | I6: =IFERROR(__xludf.DUMMYFUNCTION("if(OR(B6="""",E6=""""),"""", LET( Nama, B6, SKU, C6, Estimasi, E6, QtyOrder, F6, FilterTrans, FILTER( Transaksi!B:H, Transaksi!F:F=""Barang Datang"", Transaksi!D:D=Nama, Transaksi!E:E=SKU ), TotalDatang, IFERROR(SUM(IND"&"EX(FilterTrans,,7)), 0), TanggalDatang, IFERROR(MAX(INDEX(FilterTrans,,1)), 0), SelisihQty, QtyOrder-TotalDatang, SelisihHari, TanggalDatang-Estimasi, KeteranganQty, IF(SelisihQty=0, ""Oke"", IF(SelisihQty>0, ""Kurang "" & SelisihQty & "&""" pcs"", ""Lebih "" & ABS(SelisihQty) & "" pcs"")), KeteranganHari, IF(TanggalDatang=0, ""Belum datang"", IF(SelisihHari=0, """", IF(SelisihHari>0, ""Terlambat "" & SelisihHari & "" hari"", ""Lebih cepat "" & ABS(SelisihHari) & """&" hari""))), Hasil, IF(TanggalDatang=0, KeteranganHari, IF(AND(SelisihQty=0, SelisihHari=0), ""Oke"", IF(SelisihQty=0, KeteranganHari, IF(SelisihHari=0, KeteranganQty, KeteranganHari & "" dengan "" & LOWER(KeteranganQty))))), Hasi"&"l ))"),"Belum datang") -> Belum datang
A7: =IF(B7<>"",ROW(B7)-ROW($B$1),"") -> 6 | B7: TORCH 733 | C7: {=IFS(B7="","",COUNTIF('Master Barang'!B:B,B7)=0,SUBSTITUTE(TRIM(B7)," ","-"),COUNTIF('Master Barang'!B:B,B7)=1,XLOOKUP(B7,'Master Barang'!B:B,'Master Barang'!C:C,,,1))} -> 016B/TORCH-733 | D7: 45757 | E7: 45762 | F7: 15 | G7: 200000 | H7: Open | I7: =IFERROR(__xludf.DUMMYFUNCTION("if(OR(B7="""",E7=""""),"""", LET( Nama, B7, SKU, C7, Estimasi, E7, QtyOrder, F7, FilterTrans, FILTER( Transaksi!B:H, Transaksi!F:F=""Barang Datang"", Transaksi!D:D=Nama, Transaksi!E:E=SKU ), TotalDatang, IFERROR(SUM(IND"&"EX(FilterTrans,,7)), 0), TanggalDatang, IFERROR(MAX(INDEX(FilterTrans,,1)), 0), SelisihQty, QtyOrder-TotalDatang, SelisihHari, TanggalDatang-Estimasi, KeteranganQty, IF(SelisihQty=0, ""Oke"", IF(SelisihQty>0, ""Kurang "" & SelisihQty & "&""" pcs"", ""Lebih "" & ABS(SelisihQty) & "" pcs"")), KeteranganHari, IF(TanggalDatang=0, ""Belum datang"", IF(SelisihHari=0, """", IF(SelisihHari>0, ""Terlambat "" & SelisihHari & "" hari"", ""Lebih cepat "" & ABS(SelisihHari) & """&" hari""))), Hasil, IF(TanggalDatang=0, KeteranganHari, IF(AND(SelisihQty=0, SelisihHari=0), ""Oke"", IF(SelisihQty=0, KeteranganHari, IF(SelisihHari=0, KeteranganQty, KeteranganHari & "" dengan "" & LOWER(KeteranganQty))))), Hasi"&"l ))"),"Belum datang") -> Belum datang
A8: =IF(B8<>"",ROW(B8)-ROW($B$1),"") -> 7 | B8: SARUNG TANGAN | C8: {=IFS(B8="","",COUNTIF('Master Barang'!B:B,B8)=0,SUBSTITUTE(TRIM(B8)," ","-"),COUNTIF('Master Barang'!B:B,B8)=1,XLOOKUP(B8,'Master Barang'!B:B,'Master Barang'!C:C,,,1))} -> 901-SARUNGTANGAN | D8: 45759 | E8: 45764 | F8: 60 | G8: 20000 | H8: Open | I8: =IFERROR(__xludf.DUMMYFUNCTION("if(OR(B8="""",E8=""""),"""", LET( Nama, B8, SKU, C8, Estimasi, E8, QtyOrder, F8, FilterTrans, FILTER( Transaksi!B:H, Transaksi!F:F=""Barang Datang"", Transaksi!D:D=Nama, Transaksi!E:E=SKU ), TotalDatang, IFERROR(SUM(IND"&"EX(FilterTrans,,7)), 0), TanggalDatang, IFERROR(MAX(INDEX(FilterTrans,,1)), 0), SelisihQty, QtyOrder-TotalDatang, SelisihHari, TanggalDatang-Estimasi, KeteranganQty, IF(SelisihQty=0, ""Oke"", IF(SelisihQty>0, ""Kurang "" & SelisihQty & "&""" pcs"", ""Lebih "" & ABS(SelisihQty) & "" pcs"")), KeteranganHari, IF(TanggalDatang=0, ""Belum datang"", IF(SelisihHari=0, """", IF(SelisihHari>0, ""Terlambat "" & SelisihHari & "" hari"", ""Lebih cepat "" & ABS(SelisihHari) & """&" hari""))), Hasil, IF(TanggalDatang=0, KeteranganHari, IF(AND(SelisihQty=0, SelisihHari=0), ""Oke"", IF(SelisihQty=0, KeteranganHari, IF(SelisihHari=0, KeteranganQty, KeteranganHari & "" dengan "" & LOWER(KeteranganQty))))), Hasi"&"l ))"),"Belum datang") -> Belum datang
A9: =IF(B9<>"",ROW(B9)-ROW($B$1),"") -> 8 | B9: TIES SS 30 | C9: {=IFS(B9="","",COUNTIF('Master Barang'!B:B,B9)=0,SUBSTITUTE(TRIM(B9)," ","-"),COUNTIF('Master Barang'!B:B,B9)=1,XLOOKUP(B9,'Master Barang'!B:B,'Master Barang'!C:C,,,1))} -> 221-TIES-SS-30 | D9: 45762 | E9: 45767 | F9: 40 | G9: 40000 | H9: Open | I9: =IFERROR(__xludf.DUMMYFUNCTION("if(OR(B9="""",E9=""""),"""", LET( Nama, B9, SKU, C9, Estimasi, E9, QtyOrder, F9, FilterTrans, FILTER( Transaksi!B:H, Transaksi!F:F=""Barang Datang"", Transaksi!D:D=Nama, Transaksi!E:E=SKU ), TotalDatang, IFERROR(SUM(IND"&"EX(FilterTrans,,7)), 0), TanggalDatang, IFERROR(MAX(INDEX(FilterTrans,,1)), 0), SelisihQty, QtyOrder-TotalDatang, SelisihHari, TanggalDatang-Estimasi, KeteranganQty, IF(SelisihQty=0, ""Oke"", IF(SelisihQty>0, ""Kurang "" & SelisihQty & "&""" pcs"", ""Lebih "" & ABS(SelisihQty) & "" pcs"")), KeteranganHari, IF(TanggalDatang=0, ""Belum datang"", IF(SelisihHari=0, """", IF(SelisihHari>0, ""Terlambat "" & SelisihHari & "" hari"", ""Lebih cepat "" & ABS(SelisihHari) & """&" hari""))), Hasil, IF(TanggalDatang=0, KeteranganHari, IF(AND(SelisihQty=0, SelisihHari=0), ""Oke"", IF(SelisihQty=0, KeteranganHari, IF(SelisihHari=0, KeteranganQty, KeteranganHari & "" dengan "" & LOWER(KeteranganQty))))), Hasi"&"l ))"),"Belum datang") -> Belum datang
A10: =IF(B10<>"",ROW(B10)-ROW($B$1),"") -> 9 | B10: JUMBO 1/2 PVC | C10: {=IFS(B10="","",COUNTIF('Master Barang'!B:B,B10)=0,SUBSTITUTE(TRIM(B10)," ","-"),COUNTIF('Master Barang'!B:B,B10)=1,XLOOKUP(B10,'Master Barang'!B:B,'Master Barang'!C:C,,,1))} -> 702-JUMBO-1/2-PVC | D10: 45765 | E10: 45770 | F10: 80 | G10: 8000 | H10: Open | I10: =IFERROR(__xludf.DUMMYFUNCTION("if(OR(B10="""",E10=""""),"""", LET( Nama, B10, SKU, C10, Estimasi, E10, QtyOrder, F10, FilterTrans, FILTER( Transaksi!B:H, Transaksi!F:F=""Barang Datang"", Transaksi!D:D=Nama, Transaksi!E:E=SKU ), TotalDatang, IFERROR(S"&"UM(INDEX(FilterTrans,,7)), 0), TanggalDatang, IFERROR(MAX(INDEX(FilterTrans,,1)), 0), SelisihQty, QtyOrder-TotalDatang, SelisihHari, TanggalDatang-Estimasi, KeteranganQty, IF(SelisihQty=0, ""Oke"", IF(SelisihQty>0, ""Kurang "" & Selisih"&"Qty & "" pcs"", ""Lebih "" & ABS(SelisihQty) & "" pcs"")), KeteranganHari, IF(TanggalDatang=0, ""Belum datang"", IF(SelisihHari=0, """", IF(SelisihHari>0, ""Terlambat "" & SelisihHari & "" hari"", ""Lebih cepat "" & ABS(SelisihHari"&") & "" hari""))), Hasil, IF(TanggalDatang=0, KeteranganHari, IF(AND(SelisihQty=0, SelisihHari=0), ""Oke"", IF(SelisihQty=0, KeteranganHari, IF(SelisihHari=0, KeteranganQty, KeteranganHari & "" dengan "" & LOWER(KeteranganQty))))), "&" Hasil ))"),"Belum datang") -> Belum datang
A11: =IF(B11<>"",ROW(B11)-ROW($B$1),"") -> 10 | B11: CUT KACA | C11: {=IFS(B11="","",COUNTIF('Master Barang'!B:B,B11)=0,SUBSTITUTE(TRIM(B11)," ","-"),COUNTIF('Master Barang'!B:B,B11)=1,XLOOKUP(B11,'Master Barang'!B:B,'Master Barang'!C:C,,,1))} -> 026D/CUT-KACA | D11: 45769 | E11: 45775 | F11: 25 | G11: 12000 | H11: Open | I11: =IFERROR(__xludf.DUMMYFUNCTION("if(OR(B11="""",E11=""""),"""", LET( Nama, B11, SKU, C11, Estimasi, E11, QtyOrder, F11, FilterTrans, FILTER( Transaksi!B:H, Transaksi!F:F=""Barang Datang"", Transaksi!D:D=Nama, Transaksi!E:E=SKU ), TotalDatang, IFERROR(S"&"UM(INDEX(FilterTrans,,7)), 0), TanggalDatang, IFERROR(MAX(INDEX(FilterTrans,,1)), 0), SelisihQty, QtyOrder-TotalDatang, SelisihHari, TanggalDatang-Estimasi, KeteranganQty, IF(SelisihQty=0, ""Oke"", IF(SelisihQty>0, ""Kurang "" & Selisih"&"Qty & "" pcs"", ""Lebih "" & ABS(SelisihQty) & "" pcs"")), KeteranganHari, IF(TanggalDatang=0, ""Belum datang"", IF(SelisihHari=0, """", IF(SelisihHari>0, ""Terlambat "" & SelisihHari & "" hari"", ""Lebih cepat "" & ABS(SelisihHari"&") & "" hari""))), Hasil, IF(TanggalDatang=0, KeteranganHari, IF(AND(SelisihQty=0, SelisihHari=0), ""Oke"", IF(SelisihQty=0, KeteranganHari, IF(SelisihHari=0, KeteranganQty, KeteranganHari & "" dengan "" & LOWER(KeteranganQty))))), "&" Hasil ))"),"Belum datang") -> Belum datang
A12: =IF(B12<>"",ROW(B12)-ROW($B$1),"") | C12: {=IFS(B12="","",COUNTIF('Master Barang'!B:B,B12)=0,SUBSTITUTE(TRIM(B12)," ","-"),COUNTIF('Master Barang'!B:B,B12)=1,XLOOKUP(B12,'Master Barang'!B:B,'Master Barang'!C:C,,,1))} | I12: =IFERROR(__xludf.DUMMYFUNCTION("if(OR(B12="""",E12=""""),"""", LET( Nama, B12, SKU, C12, Estimasi, E12, QtyOrder, F12, FilterTrans, FILTER( Transaksi!B:H, Transaksi!F:F=""Barang Datang"", Transaksi!D:D=Nama, Transaksi!E:E=SKU ), TotalDatang, IFERROR(S"&"UM(INDEX(FilterTrans,,7)), 0), TanggalDatang, IFERROR(MAX(INDEX(FilterTrans,,1)), 0), SelisihQty, QtyOrder-TotalDatang, SelisihHari, TanggalDatang-Estimasi, KeteranganQty, IF(SelisihQty=0, ""Oke"", IF(SelisihQty>0, ""Kurang "" & Selisih"&"Qty & "" pcs"", ""Lebih "" & ABS(SelisihQty) & "" pcs"")), KeteranganHari, IF(TanggalDatang=0, ""Belum datang"", IF(SelisihHari=0, """", IF(SelisihHari>0, ""Terlambat "" & SelisihHari & "" hari"", ""Lebih cepat "" & ABS(SelisihHari"&") & "" hari""))), Hasil, IF(TanggalDatang=0, KeteranganHari, IF(AND(SelisihQty=0, SelisihHari=0), ""Oke"", IF(SelisihQty=0, KeteranganHari, IF(SelisihHari=0, KeteranganQty, KeteranganHari & "" dengan "" & LOWER(KeteranganQty))))), "&" Hasil ))"),"")
A13: =IF(B13<>"",ROW(B13)-ROW($B$1),"") | C13: {=IFS(B13="","",COUNTIF('Master Barang'!B:B,B13)=0,SUBSTITUTE(TRIM(B13)," ","-"),COUNTIF('Master Barang'!B:B,B13)=1,XLOOKUP(B13,'Master Barang'!B:B,'Master Barang'!C:C,,,1))} | I13: =IFERROR(__xludf.DUMMYFUNCTION("if(OR(B13="""",E13=""""),"""", LET( Nama, B13, SKU, C13, Estimasi, E13, QtyOrder, F13, FilterTrans, FILTER( Transaksi!B:H, Transaksi!F:F=""Barang Datang"", Transaksi!D:D=Nama, Transaksi!E:E=SKU ), TotalDatang, IFERROR(S"&"UM(INDEX(FilterTrans,,7)), 0), TanggalDatang, IFERROR(MAX(INDEX(FilterTrans,,1)), 0), SelisihQty, QtyOrder-TotalDatang, SelisihHari, TanggalDatang-Estimasi, KeteranganQty, IF(SelisihQty=0, ""Oke"", IF(SelisihQty>0, ""Kurang "" & Selisih"&"Qty & "" pcs"", ""Lebih "" & ABS(SelisihQty) & "" pcs"")), KeteranganHari, IF(TanggalDatang=0, ""Belum datang"", IF(SelisihHari=0, """", IF(SelisihHari>0, ""Terlambat "" & SelisihHari & "" hari"", ""Lebih cepat "" & ABS(SelisihHari"&") & "" hari""))), Hasil, IF(TanggalDatang=0, KeteranganHari, IF(AND(SelisihQty=0, SelisihHari=0), ""Oke"", IF(SelisihQty=0, KeteranganHari, IF(SelisihHari=0, KeteranganQty, KeteranganHari & "" dengan "" & LOWER(KeteranganQty))))), "&" Hasil ))"),"")
A14: =IF(B14<>"",ROW(B14)-ROW($B$1),"") | C14: {=IFS(B14="","",COUNTIF('Master Barang'!B:B,B14)=0,SUBSTITUTE(TRIM(B14)," ","-"),COUNTIF('Master Barang'!B:B,B14)=1,XLOOKUP(B14,'Master Barang'!B:B,'Master Barang'!C:C,,,1))} | I14: =IFERROR(__xludf.DUMMYFUNCTION("if(OR(B14="""",E14=""""),"""", LET( Nama, B14, SKU, C14, Estimasi, E14, QtyOrder, F14, FilterTrans, FILTER( Transaksi!B:H, Transaksi!F:F=""Barang Datang"", Transaksi!D:D=Nama, Transaksi!E:E=SKU ), TotalDatang, IFERROR(S"&"UM(INDEX(FilterTrans,,7)), 0), TanggalDatang, IFERROR(MAX(INDEX(FilterTrans,,1)), 0), SelisihQty, QtyOrder-TotalDatang, SelisihHari, TanggalDatang-Estimasi, KeteranganQty, IF(SelisihQty=0, ""Oke"", IF(SelisihQty>0, ""Kurang "" & Selisih"&"Qty & "" pcs"", ""Lebih "" & ABS(SelisihQty) & "" pcs"")), KeteranganHari, IF(TanggalDatang=0, ""Belum datang"", IF(SelisihHari=0, """", IF(SelisihHari>0, ""Terlambat "" & SelisihHari & "" hari"", ""Lebih cepat "" & ABS(SelisihHari"&") & "" hari""))), Hasil, IF(TanggalDatang=0, KeteranganHari, IF(AND(SelisihQty=0, SelisihHari=0), ""Oke"", IF(SelisihQty=0, KeteranganHari, IF(SelisihHari=0, KeteranganQty, KeteranganHari & "" dengan "" & LOWER(KeteranganQty))))), "&" Hasil ))"),"")
A15: =IF(B15<>"",ROW(B15)-ROW($B$1),"") | C15: {=IFS(B15="","",COUNTIF('Master Barang'!B:B,B15)=0,SUBSTITUTE(TRIM(B15)," ","-"),COUNTIF('Master Barang'!B:B,B15)=1,XLOOKUP(B15,'Master Barang'!B:B,'Master Barang'!C:C,,,1))} | I15: =IFERROR(__xludf.DUMMYFUNCTION("if(OR(B15="""",E15=""""),"""", LET( Nama, B15, SKU, C15, Estimasi, E15, QtyOrder, F15, FilterTrans, FILTER( Transaksi!B:H, Transaksi!F:F=""Barang Datang"", Transaksi!D:D=Nama, Transaksi!E:E=SKU ), TotalDatang, IFERROR(S"&"UM(INDEX(FilterTrans,,7)), 0), TanggalDatang, IFERROR(MAX(INDEX(FilterTrans,,1)), 0), SelisihQty, QtyOrder-TotalDatang, SelisihHari, TanggalDatang-Estimasi, KeteranganQty, IF(SelisihQty=0, ""Oke"", IF(SelisihQty>0, ""Kurang "" & Selisih"&"Qty & "" pcs"", ""Lebih "" & ABS(SelisihQty) & "" pcs"")), KeteranganHari, IF(TanggalDatang=0, ""Belum datang"", IF(SelisihHari=0, """", IF(SelisihHari>0, ""Terlambat "" & SelisihHari & "" hari"", ""Lebih cepat "" & ABS(SelisihHari"&") & "" hari""))), Hasil, IF(TanggalDatang=0, KeteranganHari, IF(AND(SelisihQty=0, SelisihHari=0), ""Oke"", IF(SelisihQty=0, KeteranganHari, IF(SelisihHari=0, KeteranganQty, KeteranganHari & "" dengan "" & LOWER(KeteranganQty))))), "&" Hasil ))"),"")
A16: =IF(B16<>"",ROW(B16)-ROW($B$1),"") | C16: {=IFS(B16="","",COUNTIF('Master Barang'!B:B,B16)=0,SUBSTITUTE(TRIM(B16)," ","-"),COUNTIF('Master Barang'!B:B,B16)=1,XLOOKUP(B16,'Master Barang'!B:B,'Master Barang'!C:C,,,1))} | I16: =IFERROR(__xludf.DUMMYFUNCTION("if(OR(B16="""",E16=""""),"""", LET( Nama, B16, SKU, C16, Estimasi, E16, QtyOrder, F16, FilterTrans, FILTER( Transaksi!B:H, Transaksi!F:F=""Barang Datang"", Transaksi!D:D=Nama, Transaksi!E:E=SKU ), TotalDatang, IFERROR(S"&"UM(INDEX(FilterTrans,,7)), 0), TanggalDatang, IFERROR(MAX(INDEX(FilterTrans,,1)), 0), SelisihQty, QtyOrder-TotalDatang, SelisihHari, TanggalDatang-Estimasi, KeteranganQty, IF(SelisihQty=0, ""Oke"", IF(SelisihQty>0, ""Kurang "" & Selisih"&"Qty & "" pcs"", ""Lebih "" & ABS(SelisihQty) & "" pcs"")), KeteranganHari, IF(TanggalDatang=0, ""Belum datang"", IF(SelisihHari=0, """", IF(SelisihHari>0, ""Terlambat "" & SelisihHari & "" hari"", ""Lebih cepat "" & ABS(SelisihHari"&") & "" hari""))), Hasil, IF(TanggalDatang=0, KeteranganHari, IF(AND(SelisihQty=0, SelisihHari=0), ""Oke"", IF(SelisihQty=0, KeteranganHari, IF(SelisihHari=0, KeteranganQty, KeteranganHari & "" dengan "" & LOWER(KeteranganQty))))), "&" Hasil ))"),"")
A17: =IF(B17<>"",ROW(B17)-ROW($B$1),"") | C17: {=IFS(B17="","",COUNTIF('Master Barang'!B:B,B17)=0,SUBSTITUTE(TRIM(B17)," ","-"),COUNTIF('Master Barang'!B:B,B17)=1,XLOOKUP(B17,'Master Barang'!B:B,'Master Barang'!C:C,,,1))} | I17: =IFERROR(__xludf.DUMMYFUNCTION("if(OR(B17="""",E17=""""),"""", LET( Nama, B17, SKU, C17, Estimasi, E17, QtyOrder, F17, FilterTrans, FILTER( Transaksi!B:H, Transaksi!F:F=""Barang Datang"", Transaksi!D:D=Nama, Transaksi!E:E=SKU ), TotalDatang, IFERROR(S"&"UM(INDEX(FilterTrans,,7)), 0), TanggalDatang, IFERROR(MAX(INDEX(FilterTrans,,1)), 0), SelisihQty, QtyOrder-TotalDatang, SelisihHari, TanggalDatang-Estimasi, KeteranganQty, IF(SelisihQty=0, ""Oke"", IF(SelisihQty>0, ""Kurang "" & Selisih"&"Qty & "" pcs"", ""Lebih "" & ABS(SelisihQty) & "" pcs"")), KeteranganHari, IF(TanggalDatang=0, ""Belum datang"", IF(SelisihHari=0, """", IF(SelisihHari>0, ""Terlambat "" & SelisihHari & "" hari"", ""Lebih cepat "" & ABS(SelisihHari"&") & "" hari""))), Hasil, IF(TanggalDatang=0, KeteranganHari, IF(AND(SelisihQty=0, SelisihHari=0), ""Oke"", IF(SelisihQty=0, KeteranganHari, IF(SelisihHari=0, KeteranganQty, KeteranganHari & "" dengan "" & LOWER(KeteranganQty))))), "&" Hasil ))"),"")
A18: =IF(B18<>"",ROW(B18)-ROW($B$1),"") | C18: {=IFS(B18="","",COUNTIF('Master Barang'!B:B,B18)=0,SUBSTITUTE(TRIM(B18)," ","-"),COUNTIF('Master Barang'!B:B,B18)=1,XLOOKUP(B18,'Master Barang'!B:B,'Master Barang'!C:C,,,1))} | I18: =IFERROR(__xludf.DUMMYFUNCTION("if(OR(B18="""",E18=""""),"""", LET( Nama, B18, SKU, C18, Estimasi, E18, QtyOrder, F18, FilterTrans, FILTER( Transaksi!B:H, Transaksi!F:F=""Barang Datang"", Transaksi!D:D=Nama, Transaksi!E:E=SKU ), TotalDatang, IFERROR(S"&"UM(INDEX(FilterTrans,,7)), 0), TanggalDatang, IFERROR(MAX(INDEX(FilterTrans,,1)), 0), SelisihQty, QtyOrder-TotalDatang, SelisihHari, TanggalDatang-Estimasi, KeteranganQty, IF(SelisihQty=0, ""Oke"", IF(SelisihQty>0, ""Kurang "" & Selisih"&"Qty & "" pcs"", ""Lebih "" & ABS(SelisihQty) & "" pcs"")), KeteranganHari, IF(TanggalDatang=0, ""Belum datang"", IF(SelisihHari=0, """", IF(SelisihHari>0, ""Terlambat "" & SelisihHari & "" hari"", ""Lebih cepat "" & ABS(SelisihHari"&") & "" hari""))), Hasil, IF(TanggalDatang=0, KeteranganHari, IF(AND(SelisihQty=0, SelisihHari=0), ""Oke"", IF(SelisihQty=0, KeteranganHari, IF(SelisihHari=0, KeteranganQty, KeteranganHari & "" dengan "" & LOWER(KeteranganQty))))), "&" Hasil ))"),"")
A19: =IF(B19<>"",ROW(B19)-ROW($B$1),"") | C19: {=IFS(B19="","",COUNTIF('Master Barang'!B:B,B19)=0,SUBSTITUTE(TRIM(B19)," ","-"),COUNTIF('Master Barang'!B:B,B19)=1,XLOOKUP(B19,'Master Barang'!B:B,'Master Barang'!C:C,,,1))} | I19: =IFERROR(__xludf.DUMMYFUNCTION("if(OR(B19="""",E19=""""),"""", LET( Nama, B19, SKU, C19, Estimasi, E19, QtyOrder, F19, FilterTrans, FILTER( Transaksi!B:H, Transaksi!F:F=""Barang Datang"", Transaksi!D:D=Nama, Transaksi!E:E=SKU ), TotalDatang, IFERROR(S"&"UM(INDEX(FilterTrans,,7)), 0), TanggalDatang, IFERROR(MAX(INDEX(FilterTrans,,1)), 0), SelisihQty, QtyOrder-TotalDatang, SelisihHari, TanggalDatang-Estimasi, KeteranganQty, IF(SelisihQty=0, ""Oke"", IF(SelisihQty>0, ""Kurang "" & Selisih"&"Qty & "" pcs"", ""Lebih "" & ABS(SelisihQty) & "" pcs"")), KeteranganHari, IF(TanggalDatang=0, ""Belum datang"", IF(SelisihHari=0, """", IF(SelisihHari>0, ""Terlambat "" & SelisihHari & "" hari"", ""Lebih cepat "" & ABS(SelisihHari"&") & "" hari""))), Hasil, IF(TanggalDatang=0, KeteranganHari, IF(AND(SelisihQty=0, SelisihHari=0), ""Oke"", IF(SelisihQty=0, KeteranganHari, IF(SelisihHari=0, KeteranganQty, KeteranganHari & "" dengan "" & LOWER(KeteranganQty))))), "&" Hasil ))"),"")
A20: =IF(B20<>"",ROW(B20)-ROW($B$1),"") | C20: {=IFS(B20="","",COUNTIF('Master Barang'!B:B,B20)=0,SUBSTITUTE(TRIM(B20)," ","-"),COUNTIF('Master Barang'!B:B,B20)=1,XLOOKUP(B20,'Master Barang'!B:B,'Master Barang'!C:C,,,1))} | I20: =IFERROR(__xludf.DUMMYFUNCTION("if(OR(B20="""",E20=""""),"""", LET( Nama, B20, SKU, C20, Estimasi, E20, QtyOrder, F20, FilterTrans, FILTER( Transaksi!B:H, Transaksi!F:F=""Barang Datang"", Transaksi!D:D=Nama, Transaksi!E:E=SKU ), TotalDatang, IFERROR(S"&"UM(INDEX(FilterTrans,,7)), 0), TanggalDatang, IFERROR(MAX(INDEX(FilterTrans,,1)), 0), SelisihQty, QtyOrder-TotalDatang, SelisihHari, TanggalDatang-Estimasi, KeteranganQty, IF(SelisihQty=0, ""Oke"", IF(SelisihQty>0, ""Kurang "" & Selisih"&"Qty & "" pcs"", ""Lebih "" & ABS(SelisihQty) & "" pcs"")), KeteranganHari, IF(TanggalDatang=0, ""Belum datang"", IF(SelisihHari=0, """", IF(SelisihHari>0, ""Terlambat "" & SelisihHari & "" hari"", ""Lebih cepat "" & ABS(SelisihHari"&") & "" hari""))), Hasil, IF(TanggalDatang=0, KeteranganHari, IF(AND(SelisihQty=0, SelisihHari=0), ""Oke"", IF(SelisihQty=0, KeteranganHari, IF(SelisihHari=0, KeteranganQty, KeteranganHari & "" dengan "" & LOWER(KeteranganQty))))), "&" Hasil ))"),"")
A21: =IF(B21<>"",ROW(B21)-ROW($B$1),"") | C21: {=IFS(B21="","",COUNTIF('Master Barang'!B:B,B21)=0,SUBSTITUTE(TRIM(B21)," ","-"),COUNTIF('Master Barang'!B:B,B21)=1,XLOOKUP(B21,'Master Barang'!B:B,'Master Barang'!C:C,,,1))} | I21: =IFERROR(__xludf.DUMMYFUNCTION("if(OR(B21="""",E21=""""),"""", LET( Nama, B21, SKU, C21, Estimasi, E21, QtyOrder, F21, FilterTrans, FILTER( Transaksi!B:H, Transaksi!F:F=""Barang Datang"", Transaksi!D:D=Nama, Transaksi!E:E=SKU ), TotalDatang, IFERROR(S"&"UM(INDEX(FilterTrans,,7)), 0), TanggalDatang, IFERROR(MAX(INDEX(FilterTrans,,1)), 0), SelisihQty, QtyOrder-TotalDatang, SelisihHari, TanggalDatang-Estimasi, KeteranganQty, IF(SelisihQty=0, ""Oke"", IF(SelisihQty>0, ""Kurang "" & Selisih"&"Qty & "" pcs"", ""Lebih "" & ABS(SelisihQty) & "" pcs"")), KeteranganHari, IF(TanggalDatang=0, ""Belum datang"", IF(SelisihHari=0, """", IF(SelisihHari>0, ""Terlambat "" & SelisihHari & "" hari"", ""Lebih cepat "" & ABS(SelisihHari"&") & "" hari""))), Hasil, IF(TanggalDatang=0, KeteranganHari, IF(AND(SelisihQty=0, SelisihHari=0), ""Oke"", IF(SelisihQty=0, KeteranganHari, IF(SelisihHari=0, KeteranganQty, KeteranganHari & "" dengan "" & LOWER(KeteranganQty))))), "&" Hasil ))"),"")
A22: =IF(B22<>"",ROW(B22)-ROW($B$1),"") | C22: {=IFS(B22="","",COUNTIF('Master Barang'!B:B,B22)=0,SUBSTITUTE(TRIM(B22)," ","-"),COUNTIF('Master Barang'!B:B,B22)=1,XLOOKUP(B22,'Master Barang'!B:B,'Master Barang'!C:C,,,1))} | I22: =IFERROR(__xludf.DUMMYFUNCTION("if(OR(B22="""",E22=""""),"""", LET( Nama, B22, SKU, C22, Estimasi, E22, QtyOrder, F22, FilterTrans, FILTER( Transaksi!B:H, Transaksi!F:F=""Barang Datang"", Transaksi!D:D=Nama, Transaksi!E:E=SKU ), TotalDatang, IFERROR(S"&"UM(INDEX(FilterTrans,,7)), 0), TanggalDatang, IFERROR(MAX(INDEX(FilterTrans,,1)), 0), SelisihQty, QtyOrder-TotalDatang, SelisihHari, TanggalDatang-Estimasi, KeteranganQty, IF(SelisihQty=0, ""Oke"", IF(SelisihQty>0, ""Kurang "" & Selisih"&"Qty & "" pcs"", ""Lebih "" & ABS(SelisihQty) & "" pcs"")), KeteranganHari, IF(TanggalDatang=0, ""Belum datang"", IF(SelisihHari=0, """", IF(SelisihHari>0, ""Terlambat "" & SelisihHari & "" hari"", ""Lebih cepat "" & ABS(SelisihHari"&") & "" hari""))), Hasil, IF(TanggalDatang=0, KeteranganHari, IF(AND(SelisihQty=0, SelisihHari=0), ""Oke"", IF(SelisihQty=0, KeteranganHari, IF(SelisihHari=0, KeteranganQty, KeteranganHari & "" dengan "" & LOWER(KeteranganQty))))), "&" Hasil ))"),"")
A23: =IF(B23<>"",ROW(B23)-ROW($B$1),"") | C23: {=IFS(B23="","",COUNTIF('Master Barang'!B:B,B23)=0,SUBSTITUTE(TRIM(B23)," ","-"),COUNTIF('Master Barang'!B:B,B23)=1,XLOOKUP(B23,'Master Barang'!B:B,'Master Barang'!C:C,,,1))} | I23: =IFERROR(__xludf.DUMMYFUNCTION("if(OR(B23="""",E23=""""),"""", LET( Nama, B23, SKU, C23, Estimasi, E23, QtyOrder, F23, FilterTrans, FILTER( Transaksi!B:H, Transaksi!F:F=""Barang Datang"", Transaksi!D:D=Nama, Transaksi!E:E=SKU ), TotalDatang, IFERROR(S"&"UM(INDEX(FilterTrans,,7)), 0), TanggalDatang, IFERROR(MAX(INDEX(FilterTrans,,1)), 0), SelisihQty, QtyOrder-TotalDatang, SelisihHari, TanggalDatang-Estimasi, KeteranganQty, IF(SelisihQty=0, ""Oke"", IF(SelisihQty>0, ""Kurang "" & Selisih"&"Qty & "" pcs"", ""Lebih "" & ABS(SelisihQty) & "" pcs"")), KeteranganHari, IF(TanggalDatang=0, ""Belum datang"", IF(SelisihHari=0, """", IF(SelisihHari>0, ""Terlambat "" & SelisihHari & "" hari"", ""Lebih cepat "" & ABS(SelisihHari"&") & "" hari""))), Hasil, IF(TanggalDatang=0, KeteranganHari, IF(AND(SelisihQty=0, SelisihHari=0), ""Oke"", IF(SelisihQty=0, KeteranganHari, IF(SelisihHari=0, KeteranganQty, KeteranganHari & "" dengan "" & LOWER(KeteranganQty))))), "&" Hasil ))"),"")
A24: =IF(B24<>"",ROW(B24)-ROW($B$1),"") | C24: {=IFS(B24="","",COUNTIF('Master Barang'!B:B,B24)=0,SUBSTITUTE(TRIM(B24)," ","-"),COUNTIF('Master Barang'!B:B,B24)=1,XLOOKUP(B24,'Master Barang'!B:B,'Master Barang'!C:C,,,1))} | I24: =IFERROR(__xludf.DUMMYFUNCTION("if(OR(B24="""",E24=""""),"""", LET( Nama, B24, SKU, C24, Estimasi, E24, QtyOrder, F24, FilterTrans, FILTER( Transaksi!B:H, Transaksi!F:F=""Barang Datang"", Transaksi!D:D=Nama, Transaksi!E:E=SKU ), TotalDatang, IFERROR(S"&"UM(INDEX(FilterTrans,,7)), 0), TanggalDatang, IFERROR(MAX(INDEX(FilterTrans,,1)), 0), SelisihQty, QtyOrder-TotalDatang, SelisihHari, TanggalDatang-Estimasi, KeteranganQty, IF(SelisihQty=0, ""Oke"", IF(SelisihQty>0, ""Kurang "" & Selisih"&"Qty & "" pcs"", ""Lebih "" & ABS(SelisihQty) & "" pcs"")), KeteranganHari, IF(TanggalDatang=0, ""Belum datang"", IF(SelisihHari=0, """", IF(SelisihHari>0, ""Terlambat "" & SelisihHari & "" hari"", ""Lebih cepat "" & ABS(SelisihHari"&") & "" hari""))), Hasil, IF(TanggalDatang=0, KeteranganHari, IF(AND(SelisihQty=0, SelisihHari=0), ""Oke"", IF(SelisihQty=0, KeteranganHari, IF(SelisihHari=0, KeteranganQty, KeteranganHari & "" dengan "" & LOWER(KeteranganQty))))), "&" Hasil ))"),"")
A25: =IF(B25<>"",ROW(B25)-ROW($B$1),"") | C25: {=IFS(B25="","",COUNTIF('Master Barang'!B:B,B25)=0,SUBSTITUTE(TRIM(B25)," ","-"),COUNTIF('Master Barang'!B:B,B25)=1,XLOOKUP(B25,'Master Barang'!B:B,'Master Barang'!C:C,,,1))} | I25: =IFERROR(__xludf.DUMMYFUNCTION("if(OR(B25="""",E25=""""),"""", LET( Nama, B25, SKU, C25, Estimasi, E25, QtyOrder, F25, FilterTrans, FILTER( Transaksi!B:H, Transaksi!F:F=""Barang Datang"", Transaksi!D:D=Nama, Transaksi!E:E=SKU ), TotalDatang, IFERROR(S"&"UM(INDEX(FilterTrans,,7)), 0), TanggalDatang, IFERROR(MAX(INDEX(FilterTrans,,1)), 0), SelisihQty, QtyOrder-TotalDatang, SelisihHari, TanggalDatang-Estimasi, KeteranganQty, IF(SelisihQty=0, ""Oke"", IF(SelisihQty>0, ""Kurang "" & Selisih"&"Qty & "" pcs"", ""Lebih "" & ABS(SelisihQty) & "" pcs"")), KeteranganHari, IF(TanggalDatang=0, ""Belum datang"", IF(SelisihHari=0, """", IF(SelisihHari>0, ""Terlambat "" & SelisihHari & "" hari"", ""Lebih cepat "" & ABS(SelisihHari"&") & "" hari""))), Hasil, IF(TanggalDatang=0, KeteranganHari, IF(AND(SelisihQty=0, SelisihHari=0), ""Oke"", IF(SelisihQty=0, KeteranganHari, IF(SelisihHari=0, KeteranganQty, KeteranganHari & "" dengan "" & LOWER(KeteranganQty))))), "&" Hasil ))"),"")
A26: =IF(B26<>"",ROW(B26)-ROW($B$1),"") | C26: {=IFS(B26="","",COUNTIF('Master Barang'!B:B,B26)=0,SUBSTITUTE(TRIM(B26)," ","-"),COUNTIF('Master Barang'!B:B,B26)=1,XLOOKUP(B26,'Master Barang'!B:B,'Master Barang'!C:C,,,1))} | I26: =IFERROR(__xludf.DUMMYFUNCTION("if(OR(B26="""",E26=""""),"""", LET( Nama, B26, SKU, C26, Estimasi, E26, QtyOrder, F26, FilterTrans, FILTER( Transaksi!B:H, Transaksi!F:F=""Barang Datang"", Transaksi!D:D=Nama, Transaksi!E:E=SKU ), TotalDatang, IFERROR(S"&"UM(INDEX(FilterTrans,,7)), 0), TanggalDatang, IFERROR(MAX(INDEX(FilterTrans,,1)), 0), SelisihQty, QtyOrder-TotalDatang, SelisihHari, TanggalDatang-Estimasi, KeteranganQty, IF(SelisihQty=0, ""Oke"", IF(SelisihQty>0, ""Kurang "" & Selisih"&"Qty & "" pcs"", ""Lebih "" & ABS(SelisihQty) & "" pcs"")), KeteranganHari, IF(TanggalDatang=0, ""Belum datang"", IF(SelisihHari=0, """", IF(SelisihHari>0, ""Terlambat "" & SelisihHari & "" hari"", ""Lebih cepat "" & ABS(SelisihHari"&") & "" hari""))), Hasil, IF(TanggalDatang=0, KeteranganHari, IF(AND(SelisihQty=0, SelisihHari=0), ""Oke"", IF(SelisihQty=0, KeteranganHari, IF(SelisihHari=0, KeteranganQty, KeteranganHari & "" dengan "" & LOWER(KeteranganQty))))), "&" Hasil ))"),"")
A27: =IF(B27<>"",ROW(B27)-ROW($B$1),"") | C27: {=IFS(B27="","",COUNTIF('Master Barang'!B:B,B27)=0,SUBSTITUTE(TRIM(B27)," ","-"),COUNTIF('Master Barang'!B:B,B27)=1,XLOOKUP(B27,'Master Barang'!B:B,'Master Barang'!C:C,,,1))} | I27: =IFERROR(__xludf.DUMMYFUNCTION("if(OR(B27="""",E27=""""),"""", LET( Nama, B27, SKU, C27, Estimasi, E27, QtyOrder, F27, FilterTrans, FILTER( Transaksi!B:H, Transaksi!F:F=""Barang Datang"", Transaksi!D:D=Nama, Transaksi!E:E=SKU ), TotalDatang, IFERROR(S"&"UM(INDEX(FilterTrans,,7)), 0), TanggalDatang, IFERROR(MAX(INDEX(FilterTrans,,1)), 0), SelisihQty, QtyOrder-TotalDatang, SelisihHari, TanggalDatang-Estimasi, KeteranganQty, IF(SelisihQty=0, ""Oke"", IF(SelisihQty>0, ""Kurang "" & Selisih"&"Qty & "" pcs"", ""Lebih "" & ABS(SelisihQty) & "" pcs"")), KeteranganHari, IF(TanggalDatang=0, ""Belum datang"", IF(SelisihHari=0, """", IF(SelisihHari>0, ""Terlambat "" & SelisihHari & "" hari"", ""Lebih cepat "" & ABS(SelisihHari"&") & "" hari""))), Hasil, IF(TanggalDatang=0, KeteranganHari, IF(AND(SelisihQty=0, SelisihHari=0), ""Oke"", IF(SelisihQty=0, KeteranganHari, IF(SelisihHari=0, KeteranganQty, KeteranganHari & "" dengan "" & LOWER(KeteranganQty))))), "&" Hasil ))"),"")
A28: =IF(B28<>"",ROW(B28)-ROW($B$1),"") | C28: {=IFS(B28="","",COUNTIF('Master Barang'!B:B,B28)=0,SUBSTITUTE(TRIM(B28)," ","-"),COUNTIF('Master Barang'!B:B,B28)=1,XLOOKUP(B28,'Master Barang'!B:B,'Master Barang'!C:C,,,1))} | I28: =IFERROR(__xludf.DUMMYFUNCTION("if(OR(B28="""",E28=""""),"""", LET( Nama, B28, SKU, C28, Estimasi, E28, QtyOrder, F28, FilterTrans, FILTER( Transaksi!B:H, Transaksi!F:F=""Barang Datang"", Transaksi!D:D=Nama, Transaksi!E:E=SKU ), TotalDatang, IFERROR(S"&"UM(INDEX(FilterTrans,,7)), 0), TanggalDatang, IFERROR(MAX(INDEX(FilterTrans,,1)), 0), SelisihQty, QtyOrder-TotalDatang, SelisihHari, TanggalDatang-Estimasi, KeteranganQty, IF(SelisihQty=0, ""Oke"", IF(SelisihQty>0, ""Kurang "" & Selisih"&"Qty & "" pcs"", ""Lebih "" & ABS(SelisihQty) & "" pcs"")), KeteranganHari, IF(TanggalDatang=0, ""Belum datang"", IF(SelisihHari=0, """", IF(SelisihHari>0, ""Terlambat "" & SelisihHari & "" hari"", ""Lebih cepat "" & ABS(SelisihHari"&") & "" hari""))), Hasil, IF(TanggalDatang=0, KeteranganHari, IF(AND(SelisihQty=0, SelisihHari=0), ""Oke"", IF(SelisihQty=0, KeteranganHari, IF(SelisihHari=0, KeteranganQty, KeteranganHari & "" dengan "" & LOWER(KeteranganQty))))), "&" Hasil ))"),"")
A29: =IF(B29<>"",ROW(B29)-ROW($B$1),"") | C29: {=IFS(B29="","",COUNTIF('Master Barang'!B:B,B29)=0,SUBSTITUTE(TRIM(B29)," ","-"),COUNTIF('Master Barang'!B:B,B29)=1,XLOOKUP(B29,'Master Barang'!B:B,'Master Barang'!C:C,,,1))} | I29: =IFERROR(__xludf.DUMMYFUNCTION("if(OR(B29="""",E29=""""),"""", LET( Nama, B29, SKU, C29, Estimasi, E29, QtyOrder, F29, FilterTrans, FILTER( Transaksi!B:H, Transaksi!F:F=""Barang Datang"", Transaksi!D:D=Nama, Transaksi!E:E=SKU ), TotalDatang, IFERROR(S"&"UM(INDEX(FilterTrans,,7)), 0), TanggalDatang, IFERROR(MAX(INDEX(FilterTrans,,1)), 0), SelisihQty, QtyOrder-TotalDatang, SelisihHari, TanggalDatang-Estimasi, KeteranganQty, IF(SelisihQty=0, ""Oke"", IF(SelisihQty>0, ""Kurang "" & Selisih"&"Qty & "" pcs"", ""Lebih "" & ABS(SelisihQty) & "" pcs"")), KeteranganHari, IF(TanggalDatang=0, ""Belum datang"", IF(SelisihHari=0, """", IF(SelisihHari>0, ""Terlambat "" & SelisihHari & "" hari"", ""Lebih cepat "" & ABS(SelisihHari"&") & "" hari""))), Hasil, IF(TanggalDatang=0, KeteranganHari, IF(AND(SelisihQty=0, SelisihHari=0), ""Oke"", IF(SelisihQty=0, KeteranganHari, IF(SelisihHari=0, KeteranganQty, KeteranganHari & "" dengan "" & LOWER(KeteranganQty))))), "&" Hasil ))"),"")
A30: =IF(B30<>"",ROW(B30)-ROW($B$1),"") | C30: {=IFS(B30="","",COUNTIF('Master Barang'!B:B,B30)=0,SUBSTITUTE(TRIM(B30)," ","-"),COUNTIF('Master Barang'!B:B,B30)=1,XLOOKUP(B30,'Master Barang'!B:B,'Master Barang'!C:C,,,1))} | I30: =IFERROR(__xludf.DUMMYFUNCTION("if(OR(B30="""",E30=""""),"""", LET( Nama, B30, SKU, C30, Estimasi, E30, QtyOrder, F30, FilterTrans, FILTER( Transaksi!B:H, Transaksi!F:F=""Barang Datang"", Transaksi!D:D=Nama, Transaksi!E:E=SKU ), TotalDatang, IFERROR(S"&"UM(INDEX(FilterTrans,,7)), 0), TanggalDatang, IFERROR(MAX(INDEX(FilterTrans,,1)), 0), SelisihQty, QtyOrder-TotalDatang, SelisihHari, TanggalDatang-Estimasi, KeteranganQty, IF(SelisihQty=0, ""Oke"", IF(SelisihQty>0, ""Kurang "" & Selisih"&"Qty & "" pcs"", ""Lebih "" & ABS(SelisihQty) & "" pcs"")), KeteranganHari, IF(TanggalDatang=0, ""Belum datang"", IF(SelisihHari=0, """", IF(SelisihHari>0, ""Terlambat "" & SelisihHari & "" hari"", ""Lebih cepat "" & ABS(SelisihHari"&") & "" hari""))), Hasil, IF(TanggalDatang=0, KeteranganHari, IF(AND(SelisihQty=0, SelisihHari=0), ""Oke"", IF(SelisihQty=0, KeteranganHari, IF(SelisihHari=0, KeteranganQty, KeteranganHari & "" dengan "" & LOWER(KeteranganQty))))), "&" Hasil ))"),"")
A31: =IF(B31<>"",ROW(B31)-ROW($B$1),"") | C31: {=IFS(B31="","",COUNTIF('Master Barang'!B:B,B31)=0,SUBSTITUTE(TRIM(B31)," ","-"),COUNTIF('Master Barang'!B:B,B31)=1,XLOOKUP(B31,'Master Barang'!B:B,'Master Barang'!C:C,,,1))} | I31: =IFERROR(__xludf.DUMMYFUNCTION("if(OR(B31="""",E31=""""),"""", LET( Nama, B31, SKU, C31, Estimasi, E31, QtyOrder, F31, FilterTrans, FILTER( Transaksi!B:H, Transaksi!F:F=""Barang Datang"", Transaksi!D:D=Nama, Transaksi!E:E=SKU ), TotalDatang, IFERROR(S"&"UM(INDEX(FilterTrans,,7)), 0), TanggalDatang, IFERROR(MAX(INDEX(FilterTrans,,1)), 0), SelisihQty, QtyOrder-TotalDatang, SelisihHari, TanggalDatang-Estimasi, KeteranganQty, IF(SelisihQty=0, ""Oke"", IF(SelisihQty>0, ""Kurang "" & Selisih"&"Qty & "" pcs"", ""Lebih "" & ABS(SelisihQty) & "" pcs"")), KeteranganHari, IF(TanggalDatang=0, ""Belum datang"", IF(SelisihHari=0, """", IF(SelisihHari>0, ""Terlambat "" & SelisihHari & "" hari"", ""Lebih cepat "" & ABS(SelisihHari"&") & "" hari""))), Hasil, IF(TanggalDatang=0, KeteranganHari, IF(AND(SelisihQty=0, SelisihHari=0), ""Oke"", IF(SelisihQty=0, KeteranganHari, IF(SelisihHari=0, KeteranganQty, KeteranganHari & "" dengan "" & LOWER(KeteranganQty))))), "&" Hasil ))"),"")
A32: =IF(B32<>"",ROW(B32)-ROW($B$1),"") | C32: {=IFS(B32="","",COUNTIF('Master Barang'!B:B,B32)=0,SUBSTITUTE(TRIM(B32)," ","-"),COUNTIF('Master Barang'!B:B,B32)=1,XLOOKUP(B32,'Master Barang'!B:B,'Master Barang'!C:C,,,1))} | I32: =IFERROR(__xludf.DUMMYFUNCTION("if(OR(B32="""",E32=""""),"""", LET( Nama, B32, SKU, C32, Estimasi, E32, QtyOrder, F32, FilterTrans, FILTER( Transaksi!B:H, Transaksi!F:F=""Barang Datang"", Transaksi!D:D=Nama, Transaksi!E:E=SKU ), TotalDatang, IFERROR(S"&"UM(INDEX(FilterTrans,,7)), 0), TanggalDatang, IFERROR(MAX(INDEX(FilterTrans,,1)), 0), SelisihQty, QtyOrder-TotalDatang, SelisihHari, TanggalDatang-Estimasi, KeteranganQty, IF(SelisihQty=0, ""Oke"", IF(SelisihQty>0, ""Kurang "" & Selisih"&"Qty & "" pcs"", ""Lebih "" & ABS(SelisihQty) & "" pcs"")), KeteranganHari, IF(TanggalDatang=0, ""Belum datang"", IF(SelisihHari=0, """", IF(SelisihHari>0, ""Terlambat "" & SelisihHari & "" hari"", ""Lebih cepat "" & ABS(SelisihHari"&") & "" hari""))), Hasil, IF(TanggalDatang=0, KeteranganHari, IF(AND(SelisihQty=0, SelisihHari=0), ""Oke"", IF(SelisihQty=0, KeteranganHari, IF(SelisihHari=0, KeteranganQty, KeteranganHari & "" dengan "" & LOWER(KeteranganQty))))), "&" Hasil ))"),"")
A33: =IF(B33<>"",ROW(B33)-ROW($B$1),"") | C33: {=IFS(B33="","",COUNTIF('Master Barang'!B:B,B33)=0,SUBSTITUTE(TRIM(B33)," ","-"),COUNTIF('Master Barang'!B:B,B33)=1,XLOOKUP(B33,'Master Barang'!B:B,'Master Barang'!C:C,,,1))} | I33: =IFERROR(__xludf.DUMMYFUNCTION("if(OR(B33="""",E33=""""),"""", LET( Nama, B33, SKU, C33, Estimasi, E33, QtyOrder, F33, FilterTrans, FILTER( Transaksi!B:H, Transaksi!F:F=""Barang Datang"", Transaksi!D:D=Nama, Transaksi!E:E=SKU ), TotalDatang, IFERROR(S"&"UM(INDEX(FilterTrans,,7)), 0), TanggalDatang, IFERROR(MAX(INDEX(FilterTrans,,1)), 0), SelisihQty, QtyOrder-TotalDatang, SelisihHari, TanggalDatang-Estimasi, KeteranganQty, IF(SelisihQty=0, ""Oke"", IF(SelisihQty>0, ""Kurang "" & Selisih"&"Qty & "" pcs"", ""Lebih "" & ABS(SelisihQty) & "" pcs"")), KeteranganHari, IF(TanggalDatang=0, ""Belum datang"", IF(SelisihHari=0, """", IF(SelisihHari>0, ""Terlambat "" & SelisihHari & "" hari"", ""Lebih cepat "" & ABS(SelisihHari"&") & "" hari""))), Hasil, IF(TanggalDatang=0, KeteranganHari, IF(AND(SelisihQty=0, SelisihHari=0), ""Oke"", IF(SelisihQty=0, KeteranganHari, IF(SelisihHari=0, KeteranganQty, KeteranganHari & "" dengan "" & LOWER(KeteranganQty))))), "&" Hasil ))"),"")
A34: =IF(B34<>"",ROW(B34)-ROW($B$1),"") | C34: {=IFS(B34="","",COUNTIF('Master Barang'!B:B,B34)=0,SUBSTITUTE(TRIM(B34)," ","-"),COUNTIF('Master Barang'!B:B,B34)=1,XLOOKUP(B34,'Master Barang'!B:B,'Master Barang'!C:C,,,1))} | I34: =IFERROR(__xludf.DUMMYFUNCTION("if(OR(B34="""",E34=""""),"""", LET( Nama, B34, SKU, C34, Estimasi, E34, QtyOrder, F34, FilterTrans, FILTER( Transaksi!B:H, Transaksi!F:F=""Barang Datang"", Transaksi!D:D=Nama, Transaksi!E:E=SKU ), TotalDatang, IFERROR(S"&"UM(INDEX(FilterTrans,,7)), 0), TanggalDatang, IFERROR(MAX(INDEX(FilterTrans,,1)), 0), SelisihQty, QtyOrder-TotalDatang, SelisihHari, TanggalDatang-Estimasi, KeteranganQty, IF(SelisihQty=0, ""Oke"", IF(SelisihQty>0, ""Kurang "" & Selisih"&"Qty & "" pcs"", ""Lebih "" & ABS(SelisihQty) & "" pcs"")), KeteranganHari, IF(TanggalDatang=0, ""Belum datang"", IF(SelisihHari=0, """", IF(SelisihHari>0, ""Terlambat "" & SelisihHari & "" hari"", ""Lebih cepat "" & ABS(SelisihHari"&") & "" hari""))), Hasil, IF(TanggalDatang=0, KeteranganHari, IF(AND(SelisihQty=0, SelisihHari=0), ""Oke"", IF(SelisihQty=0, KeteranganHari, IF(SelisihHari=0, KeteranganQty, KeteranganHari & "" dengan "" & LOWER(KeteranganQty))))), "&" Hasil ))"),"")
A35: =IF(B35<>"",ROW(B35)-ROW($B$1),"") | C35: {=IFS(B35="","",COUNTIF('Master Barang'!B:B,B35)=0,SUBSTITUTE(TRIM(B35)," ","-"),COUNTIF('Master Barang'!B:B,B35)=1,XLOOKUP(B35,'Master Barang'!B:B,'Master Barang'!C:C,,,1))} | I35: =IFERROR(__xludf.DUMMYFUNCTION("if(OR(B35="""",E35=""""),"""", LET( Nama, B35, SKU, C35, Estimasi, E35, QtyOrder, F35, FilterTrans, FILTER( Transaksi!B:H, Transaksi!F:F=""Barang Datang"", Transaksi!D:D=Nama, Transaksi!E:E=SKU ), TotalDatang, IFERROR(S"&"UM(INDEX(FilterTrans,,7)), 0), TanggalDatang, IFERROR(MAX(INDEX(FilterTrans,,1)), 0), SelisihQty, QtyOrder-TotalDatang, SelisihHari, TanggalDatang-Estimasi, KeteranganQty, IF(SelisihQty=0, ""Oke"", IF(SelisihQty>0, ""Kurang "" & Selisih"&"Qty & "" pcs"", ""Lebih "" & ABS(SelisihQty) & "" pcs"")), KeteranganHari, IF(TanggalDatang=0, ""Belum datang"", IF(SelisihHari=0, """", IF(SelisihHari>0, ""Terlambat "" & SelisihHari & "" hari"", ""Lebih cepat "" & ABS(SelisihHari"&") & "" hari""))), Hasil, IF(TanggalDatang=0, KeteranganHari, IF(AND(SelisihQty=0, SelisihHari=0), ""Oke"", IF(SelisihQty=0, KeteranganHari, IF(SelisihHari=0, KeteranganQty, KeteranganHari & "" dengan "" & LOWER(KeteranganQty))))), "&" Hasil ))"),"")
A36: =IF(B36<>"",ROW(B36)-ROW($B$1),"") | C36: {=IFS(B36="","",COUNTIF('Master Barang'!B:B,B36)=0,SUBSTITUTE(TRIM(B36)," ","-"),COUNTIF('Master Barang'!B:B,B36)=1,XLOOKUP(B36,'Master Barang'!B:B,'Master Barang'!C:C,,,1))} | I36: =IFERROR(__xludf.DUMMYFUNCTION("if(OR(B36="""",E36=""""),"""", LET( Nama, B36, SKU, C36, Estimasi, E36, QtyOrder, F36, FilterTrans, FILTER( Transaksi!B:H, Transaksi!F:F=""Barang Datang"", Transaksi!D:D=Nama, Transaksi!E:E=SKU ), TotalDatang, IFERROR(S"&"UM(INDEX(FilterTrans,,7)), 0), TanggalDatang, IFERROR(MAX(INDEX(FilterTrans,,1)), 0), SelisihQty, QtyOrder-TotalDatang, SelisihHari, TanggalDatang-Estimasi, KeteranganQty, IF(SelisihQty=0, ""Oke"", IF(SelisihQty>0, ""Kurang "" & Selisih"&"Qty & "" pcs"", ""Lebih "" & ABS(SelisihQty) & "" pcs"")), KeteranganHari, IF(TanggalDatang=0, ""Belum datang"", IF(SelisihHari=0, """", IF(SelisihHari>0, ""Terlambat "" & SelisihHari & "" hari"", ""Lebih cepat "" & ABS(SelisihHari"&") & "" hari""))), Hasil, IF(TanggalDatang=0, KeteranganHari, IF(AND(SelisihQty=0, SelisihHari=0), ""Oke"", IF(SelisihQty=0, KeteranganHari, IF(SelisihHari=0, KeteranganQty, KeteranganHari & "" dengan "" & LOWER(KeteranganQty))))), "&" Hasil ))"),"")
A37: =IF(B37<>"",ROW(B37)-ROW($B$1),"") | C37: {=IFS(B37="","",COUNTIF('Master Barang'!B:B,B37)=0,SUBSTITUTE(TRIM(B37)," ","-"),COUNTIF('Master Barang'!B:B,B37)=1,XLOOKUP(B37,'Master Barang'!B:B,'Master Barang'!C:C,,,1))} | I37: =IFERROR(__xludf.DUMMYFUNCTION("if(OR(B37="""",E37=""""),"""", LET( Nama, B37, SKU, C37, Estimasi, E37, QtyOrder, F37, FilterTrans, FILTER( Transaksi!B:H, Transaksi!F:F=""Barang Datang"", Transaksi!D:D=Nama, Transaksi!E:E=SKU ), TotalDatang, IFERROR(S"&"UM(INDEX(FilterTrans,,7)), 0), TanggalDatang, IFERROR(MAX(INDEX(FilterTrans,,1)), 0), SelisihQty, QtyOrder-TotalDatang, SelisihHari, TanggalDatang-Estimasi, KeteranganQty, IF(SelisihQty=0, ""Oke"", IF(SelisihQty>0, ""Kurang "" & Selisih"&"Qty & "" pcs"", ""Lebih "" & ABS(SelisihQty) & "" pcs"")), KeteranganHari, IF(TanggalDatang=0, ""Belum datang"", IF(SelisihHari=0, """", IF(SelisihHari>0, ""Terlambat "" & SelisihHari & "" hari"", ""Lebih cepat "" & ABS(SelisihHari"&") & "" hari""))), Hasil, IF(TanggalDatang=0, KeteranganHari, IF(AND(SelisihQty=0, SelisihHari=0), ""Oke"", IF(SelisihQty=0, KeteranganHari, IF(SelisihHari=0, KeteranganQty, KeteranganHari & "" dengan "" & LOWER(KeteranganQty))))), "&" Hasil ))"),"")
A38: =IF(B38<>"",ROW(B38)-ROW($B$1),"") | C38: {=IFS(B38="","",COUNTIF('Master Barang'!B:B,B38)=0,SUBSTITUTE(TRIM(B38)," ","-"),COUNTIF('Master Barang'!B:B,B38)=1,XLOOKUP(B38,'Master Barang'!B:B,'Master Barang'!C:C,,,1))} | I38: =IFERROR(__xludf.DUMMYFUNCTION("if(OR(B38="""",E38=""""),"""", LET( Nama, B38, SKU, C38, Estimasi, E38, QtyOrder, F38, FilterTrans, FILTER( Transaksi!B:H, Transaksi!F:F=""Barang Datang"", Transaksi!D:D=Nama, Transaksi!E:E=SKU ), TotalDatang, IFERROR(S"&"UM(INDEX(FilterTrans,,7)), 0), TanggalDatang, IFERROR(MAX(INDEX(FilterTrans,,1)), 0), SelisihQty, QtyOrder-TotalDatang, SelisihHari, TanggalDatang-Estimasi, KeteranganQty, IF(SelisihQty=0, ""Oke"", IF(SelisihQty>0, ""Kurang "" & Selisih"&"Qty & "" pcs"", ""Lebih "" & ABS(SelisihQty) & "" pcs"")), KeteranganHari, IF(TanggalDatang=0, ""Belum datang"", IF(SelisihHari=0, """", IF(SelisihHari>0, ""Terlambat "" & SelisihHari & "" hari"", ""Lebih cepat "" & ABS(SelisihHari"&") & "" hari""))), Hasil, IF(TanggalDatang=0, KeteranganHari, IF(AND(SelisihQty=0, SelisihHari=0), ""Oke"", IF(SelisihQty=0, KeteranganHari, IF(SelisihHari=0, KeteranganQty, KeteranganHari & "" dengan "" & LOWER(KeteranganQty))))), "&" Hasil ))"),"")
A39: =IF(B39<>"",ROW(B39)-ROW($B$1),"") | C39: {=IFS(B39="","",COUNTIF('Master Barang'!B:B,B39)=0,SUBSTITUTE(TRIM(B39)," ","-"),COUNTIF('Master Barang'!B:B,B39)=1,XLOOKUP(B39,'Master Barang'!B:B,'Master Barang'!C:C,,,1))} | I39: =IFERROR(__xludf.DUMMYFUNCTION("if(OR(B39="""",E39=""""),"""", LET( Nama, B39, SKU, C39, Estimasi, E39, QtyOrder, F39, FilterTrans, FILTER( Transaksi!B:H, Transaksi!F:F=""Barang Datang"", Transaksi!D:D=Nama, Transaksi!E:E=SKU ), TotalDatang, IFERROR(S"&"UM(INDEX(FilterTrans,,7)), 0), TanggalDatang, IFERROR(MAX(INDEX(FilterTrans,,1)), 0), SelisihQty, QtyOrder-TotalDatang, SelisihHari, TanggalDatang-Estimasi, KeteranganQty, IF(SelisihQty=0, ""Oke"", IF(SelisihQty>0, ""Kurang "" & Selisih"&"Qty & "" pcs"", ""Lebih "" & ABS(SelisihQty) & "" pcs"")), KeteranganHari, IF(TanggalDatang=0, ""Belum datang"", IF(SelisihHari=0, """", IF(SelisihHari>0, ""Terlambat "" & SelisihHari & "" hari"", ""Lebih cepat "" & ABS(SelisihHari"&") & "" hari""))), Hasil, IF(TanggalDatang=0, KeteranganHari, IF(AND(SelisihQty=0, SelisihHari=0), ""Oke"", IF(SelisihQty=0, KeteranganHari, IF(SelisihHari=0, KeteranganQty, KeteranganHari & "" dengan "" & LOWER(KeteranganQty))))), "&" Hasil ))"),"")
A40: =IF(B40<>"",ROW(B40)-ROW($B$1),"") | C40: {=IFS(B40="","",COUNTIF('Master Barang'!B:B,B40)=0,SUBSTITUTE(TRIM(B40)," ","-"),COUNTIF('Master Barang'!B:B,B40)=1,XLOOKUP(B40,'Master Barang'!B:B,'Master Barang'!C:C,,,1))} | I40: =IFERROR(__xludf.DUMMYFUNCTION("if(OR(B40="""",E40=""""),"""", LET( Nama, B40, SKU, C40, Estimasi, E40, QtyOrder, F40, FilterTrans, FILTER( Transaksi!B:H, Transaksi!F:F=""Barang Datang"", Transaksi!D:D=Nama, Transaksi!E:E=SKU ), TotalDatang, IFERROR(S"&"UM(INDEX(FilterTrans,,7)), 0), TanggalDatang, IFERROR(MAX(INDEX(FilterTrans,,1)), 0), SelisihQty, QtyOrder-TotalDatang, SelisihHari, TanggalDatang-Estimasi, KeteranganQty, IF(SelisihQty=0, ""Oke"", IF(SelisihQty>0, ""Kurang "" & Selisih"&"Qty & "" pcs"", ""Lebih "" & ABS(SelisihQty) & "" pcs"")), KeteranganHari, IF(TanggalDatang=0, ""Belum datang"", IF(SelisihHari=0, """", IF(SelisihHari>0, ""Terlambat "" & SelisihHari & "" hari"", ""Lebih cepat "" & ABS(SelisihHari"&") & "" hari""))), Hasil, IF(TanggalDatang=0, KeteranganHari, IF(AND(SelisihQty=0, SelisihHari=0), ""Oke"", IF(SelisihQty=0, KeteranganHari, IF(SelisihHari=0, KeteranganQty, KeteranganHari & "" dengan "" & LOWER(KeteranganQty))))), "&" Hasil ))"),"")
...

Sheet Master Barang
A1: No. | B1: Nama Unit | C1: Kode SKU | D1: Stok Awal | E1: Masuk | F1: Rusak | G1: Keluar | H1: Stok Akhir | I1: Nilai Persediaan | J1: MA | K1: Harga Jual
A2: =IF(B2<>"",ROW(B2)-ROW($B$1),"") -> 1 | B2: TEMBOK FLEX SS | C2: 001A/TEMBOKFLEX-SS | D2: 92 | E2: =SUMIFS(Transaksi!J:J, Transaksi!E:E, $C2, Transaksi!F:F, "Barang Datang")+SUMIFS(Transaksi!J:J, Transaksi!E:E,$C2,Transaksi!F:F,"Retur Penjualan") -> 0 | F2: =SUMIFS(Transaksi!K:K, Transaksi!E:E, $C2, Transaksi!F:F, "Barang Datang") + SUMIFS(Transaksi!K:K, Transaksi!E:E, $C2, Transaksi!F:F, "Retur penjualan")+SUMIFS(Transaksi!K:K, Transaksi!E:E, $C2, Transaksi!F:F,"Rusak Internal") -> 0 | G2: =SUMIFS(Transaksi!I:I, Transaksi!E:E, $C2, Transaksi!F:F, "Terjual") + SUMIFS(Transaksi!J:J, Transaksi!E:E, $C2, Transaksi!F:F, "Retur Pembelian")+SUMIFS(Transaksi!I:I, Transaksi!E:E, $C2, Transaksi!F:F, "Dipakai Sendiri") -> 0 | H2: =IF(or(D2<>"",AND(B2<>"",C2<>"")),D2+E2-F2-G2,"") -> 92 | I2: =if(AND(H2<>"",J2<>""), H2*J2,"") | K2: 15000
A3: =IF(B3<>"",ROW(B3)-ROW($B$1),"") -> 2 | B3: TAMAN PVC HIJAU | C3: 001B/TAMAN-PVC-HIJAU | D3: 91 | E3: =SUMIFS(Transaksi!J:J, Transaksi!E:E, $C3, Transaksi!F:F, "Barang Datang")+SUMIFS(Transaksi!J:J, Transaksi!E:E,$C3,Transaksi!F:F,"Retur Penjualan") -> 0 | F3: =SUMIFS(Transaksi!K:K, Transaksi!E:E, $C3, Transaksi!F:F, "Barang Datang") + SUMIFS(Transaksi!K:K, Transaksi!E:E, $C3, Transaksi!F:F, "Retur penjualan")+SUMIFS(Transaksi!K:K, Transaksi!E:E, $C3, Transaksi!F:F,"Rusak Internal") -> 0 | G3: =SUMIFS(Transaksi!I:I, Transaksi!E:E, $C3, Transaksi!F:F, "Terjual") + SUMIFS(Transaksi!J:J, Transaksi!E:E, $C3, Transaksi!F:F, "Retur Pembelian")+SUMIFS(Transaksi!I:I, Transaksi!E:E, $C3, Transaksi!F:F, "Dipakai Sendiri") -> 0 | H3: =IF(or(D3<>"",AND(B3<>"",C3<>"")),D3+E3-F3-G3,"") -> 91 | I3: =if(AND(H3<>"",J3<>""), H3*J3,"") | K3: 10000
A4: =IF(B4<>"",ROW(B4)-ROW($B$1),"") -> 3 | B4: TIES 10 HITAM | C4: 001C/TIES-10-HITAM | D4: 33 | E4: =SUMIFS(Transaksi!J:J, Transaksi!E:E, $C4, Transaksi!F:F, "Barang Datang")+SUMIFS(Transaksi!J:J, Transaksi!E:E,$C4,Transaksi!F:F,"Retur Penjualan") -> 0 | F4: =SUMIFS(Transaksi!K:K, Transaksi!E:E, $C4, Transaksi!F:F, "Barang Datang") + SUMIFS(Transaksi!K:K, Transaksi!E:E, $C4, Transaksi!F:F, "Retur penjualan")+SUMIFS(Transaksi!K:K, Transaksi!E:E, $C4, Transaksi!F:F,"Rusak Internal") -> 0 | G4: =SUMIFS(Transaksi!I:I, Transaksi!E:E, $C4, Transaksi!F:F, "Terjual") + SUMIFS(Transaksi!J:J, Transaksi!E:E, $C4, Transaksi!F:F, "Retur Pembelian")+SUMIFS(Transaksi!I:I, Transaksi!E:E, $C4, Transaksi!F:F, "Dipakai Sendiri") -> 0 | H4: =IF(or(D4<>"",AND(B4<>"",C4<>"")),D4+E4-F4-G4,"") -> 33 | I4: =if(AND(H4<>"",J4<>""), H4*J4,"") | K4: 30000
A5: =IF(B5<>"",ROW(B5)-ROW($B$1),"") -> 4 | B5: OBENG 10-16 | C5: 001D/OBENG-10-16 | D5: 64 | E5: =SUMIFS(Transaksi!J:J, Transaksi!E:E, $C5, Transaksi!F:F, "Barang Datang")+SUMIFS(Transaksi!J:J, Transaksi!E:E,$C5,Transaksi!F:F,"Retur Penjualan") -> 0 | F5: =SUMIFS(Transaksi!K:K, Transaksi!E:E, $C5, Transaksi!F:F, "Barang Datang") + SUMIFS(Transaksi!K:K, Transaksi!E:E, $C5, Transaksi!F:F, "Retur penjualan")+SUMIFS(Transaksi!K:K, Transaksi!E:E, $C5, Transaksi!F:F,"Rusak Internal") -> 0 | G5: =SUMIFS(Transaksi!I:I, Transaksi!E:E, $C5, Transaksi!F:F, "Terjual") + SUMIFS(Transaksi!J:J, Transaksi!E:E, $C5, Transaksi!F:F, "Retur Pembelian")+SUMIFS(Transaksi!I:I, Transaksi!E:E, $C5, Transaksi!F:F, "Dipakai Sendiri") -> 0 | H5: =IF(or(D5<>"",AND(B5<>"",C5<>"")),D5+E5-F5-G5,"") -> 64 | I5: =if(AND(H5<>"",J5<>""), H5*J5,"") | K5: 20000
A6: =IF(B6<>"",ROW(B6)-ROW($B$1),"") -> 5 | B6: FLEX BALING | C6: 002A/TEMBOKFLEX-BALING-CM | D6: 18 | E6: =SUMIFS(Transaksi!J:J, Transaksi!E:E, $C6, Transaksi!F:F, "Barang Datang")+SUMIFS(Transaksi!J:J, Transaksi!E:E,$C6,Transaksi!F:F,"Retur Penjualan") -> 0 | F6: =SUMIFS(Transaksi!K:K, Transaksi!E:E, $C6, Transaksi!F:F, "Barang Datang") + SUMIFS(Transaksi!K:K, Transaksi!E:E, $C6, Transaksi!F:F, "Retur penjualan")+SUMIFS(Transaksi!K:K, Transaksi!E:E, $C6, Transaksi!F:F,"Rusak Internal") -> 0 | G6: =SUMIFS(Transaksi!I:I, Transaksi!E:E, $C6, Transaksi!F:F, "Terjual") + SUMIFS(Transaksi!J:J, Transaksi!E:E, $C6, Transaksi!F:F, "Retur Pembelian")+SUMIFS(Transaksi!I:I, Transaksi!E:E, $C6, Transaksi!F:F, "Dipakai Sendiri") -> 0 | H6: =IF(or(D6<>"",AND(B6<>"",C6<>"")),D6+E6-F6-G6,"") -> 18 | I6: =if(AND(H6<>"",J6<>""), H6*J6,"") | K6: 40000
A7: =IF(B7<>"",ROW(B7)-ROW($B$1),"") -> 6 | B7: TAMAN PVC BIRU | C7: 002B/TAMAN-PVC-BIRU | D7: 87 | E7: =SUMIFS(Transaksi!J:J, Transaksi!E:E, $C7, Transaksi!F:F, "Barang Datang")+SUMIFS(Transaksi!J:J, Transaksi!E:E,$C7,Transaksi!F:F,"Retur Penjualan") -> 0 | F7: =SUMIFS(Transaksi!K:K, Transaksi!E:E, $C7, Transaksi!F:F, "Barang Datang") + SUMIFS(Transaksi!K:K, Transaksi!E:E, $C7, Transaksi!F:F, "Retur penjualan")+SUMIFS(Transaksi!K:K, Transaksi!E:E, $C7, Transaksi!F:F,"Rusak Internal") -> 0 | G7: =SUMIFS(Transaksi!I:I, Transaksi!E:E, $C7, Transaksi!F:F, "Terjual") + SUMIFS(Transaksi!J:J, Transaksi!E:E, $C7, Transaksi!F:F, "Retur Pembelian")+SUMIFS(Transaksi!I:I, Transaksi!E:E, $C7, Transaksi!F:F, "Dipakai Sendiri") -> 0 | H7: =IF(or(D7<>"",AND(B7<>"",C7<>"")),D7+E7-F7-G7,"") -> 87 | I7: =if(AND(H7<>"",J7<>""), H7*J7,"") | K7: 40000
A8: =IF(B8<>"",ROW(B8)-ROW($B$1),"") -> 7 | B8: TIES 10 PUTIH | C8: 002C/TIES-10-PUTIH | D8: 90 | E8: =SUMIFS(Transaksi!J:J, Transaksi!E:E, $C8, Transaksi!F:F, "Barang Datang")+SUMIFS(Transaksi!J:J, Transaksi!E:E,$C8,Transaksi!F:F,"Retur Penjualan") -> 0 | F8: =SUMIFS(Transaksi!K:K, Transaksi!E:E, $C8, Transaksi!F:F, "Barang Datang") + SUMIFS(Transaksi!K:K, Transaksi!E:E, $C8, Transaksi!F:F, "Retur penjualan")+SUMIFS(Transaksi!K:K, Transaksi!E:E, $C8, Transaksi!F:F,"Rusak Internal") -> 0 | G8: =SUMIFS(Transaksi!I:I, Transaksi!E:E, $C8, Transaksi!F:F, "Terjual") + SUMIFS(Transaksi!J:J, Transaksi!E:E, $C8, Transaksi!F:F, "Retur Pembelian")+SUMIFS(Transaksi!I:I, Transaksi!E:E, $C8, Transaksi!F:F, "Dipakai Sendiri") -> 0 | H8: =IF(or(D8<>"",AND(B8<>"",C8<>"")),D8+E8-F8-G8,"") -> 90 | I8: =if(AND(H8<>"",J8<>""), H8*J8,"") | K8: 15000
A9: =IF(B9<>"",ROW(B9)-ROW($B$1),"") -> 8 | B9: OBENG 13-19 | C9: 002D/OBENG-13-19 | D9: 74 | E9: =SUMIFS(Transaksi!J:J, Transaksi!E:E, $C9, Transaksi!F:F, "Barang Datang")+SUMIFS(Transaksi!J:J, Transaksi!E:E,$C9,Transaksi!F:F,"Retur Penjualan") -> 0 | F9: =SUMIFS(Transaksi!K:K, Transaksi!E:E, $C9, Transaksi!F:F, "Barang Datang") + SUMIFS(Transaksi!K:K, Transaksi!E:E, $C9, Transaksi!F:F, "Retur penjualan")+SUMIFS(Transaksi!K:K, Transaksi!E:E, $C9, Transaksi!F:F,"Rusak Internal") -> 0 | G9: =SUMIFS(Transaksi!I:I, Transaksi!E:E, $C9, Transaksi!F:F, "Terjual") + SUMIFS(Transaksi!J:J, Transaksi!E:E, $C9, Transaksi!F:F, "Retur Pembelian")+SUMIFS(Transaksi!I:I, Transaksi!E:E, $C9, Transaksi!F:F, "Dipakai Sendiri") -> 0 | H9: =IF(or(D9<>"",AND(B9<>"",C9<>"")),D9+E9-F9-G9,"") -> 74 | I9: =if(AND(H9<>"",J9<>""), H9*J9,"") | K9: 20000
A10: =IF(B10<>"",ROW(B10)-ROW($B$1),"") -> 9 | B10: TEMBOK FLEX PUTIH | C10: 003A/TEMBOKFLEX-PUTIH | D10: 40 | E10: =SUMIFS(Transaksi!J:J, Transaksi!E:E, $C10, Transaksi!F:F, "Barang Datang")+SUMIFS(Transaksi!J:J, Transaksi!E:E,$C10,Transaksi!F:F,"Retur Penjualan") -> 0 | F10: =SUMIFS(Transaksi!K:K, Transaksi!E:E, $C10, Transaksi!F:F, "Barang Datang") + SUMIFS(Transaksi!K:K, Transaksi!E:E, $C10, Transaksi!F:F, "Retur penjualan")+SUMIFS(Transaksi!K:K, Transaksi!E:E, $C10, Transaksi!F:F,"Rusak Internal") -> 0 | G10: =SUMIFS(Transaksi!I:I, Transaksi!E:E, $C10, Transaksi!F:F, "Terjual") + SUMIFS(Transaksi!J:J, Transaksi!E:E, $C10, Transaksi!F:F, "Retur Pembelian")+SUMIFS(Transaksi!I:I, Transaksi!E:E, $C10, Transaksi!F:F, "Dipakai Sendiri") -> 0 | H10: =IF(or(D10<>"",AND(B10<>"",C10<>"")),D10+E10-F10-G10,"") -> 40 | I10: =if(AND(H10<>"",J10<>""), H10*J10,"") | K10: 10000
A11: =IF(B11<>"",ROW(B11)-ROW($B$1),"") -> 10 | B11: TAMAN PVC PUTIH | C11: 003B/TAMAN-PVC-PUTIH | D11: 39 | E11: =SUMIFS(Transaksi!J:J, Transaksi!E:E, $C11, Transaksi!F:F, "Barang Datang")+SUMIFS(Transaksi!J:J, Transaksi!E:E,$C11,Transaksi!F:F,"Retur Penjualan") -> 0 | F11: =SUMIFS(Transaksi!K:K, Transaksi!E:E, $C11, Transaksi!F:F, "Barang Datang") + SUMIFS(Transaksi!K:K, Transaksi!E:E, $C11, Transaksi!F:F, "Retur penjualan")+SUMIFS(Transaksi!K:K, Transaksi!E:E, $C11, Transaksi!F:F,"Rusak Internal") -> 0 | G11: =SUMIFS(Transaksi!I:I, Transaksi!E:E, $C11, Transaksi!F:F, "Terjual") + SUMIFS(Transaksi!J:J, Transaksi!E:E, $C11, Transaksi!F:F, "Retur Pembelian")+SUMIFS(Transaksi!I:I, Transaksi!E:E, $C11, Transaksi!F:F, "Dipakai Sendiri") -> 0 | H11: =IF(or(D11<>"",AND(B11<>"",C11<>"")),D11+E11-F11-G11,"") -> 39 | I11: =if(AND(H11<>"",J11<>""), H11*J11,"") | K11: 15000
A12: =IF(B12<>"",ROW(B12)-ROW($B$1),"") -> 11 | B12: TIES 15 HITAM | C12: 003C/TIES-15-HITAM | D12: 29 | E12: =SUMIFS(Transaksi!J:J, Transaksi!E:E, $C12, Transaksi!F:F, "Barang Datang")+SUMIFS(Transaksi!J:J, Transaksi!E:E,$C12,Transaksi!F:F,"Retur Penjualan") -> 0 | F12: =SUMIFS(Transaksi!K:K, Transaksi!E:E, $C12, Transaksi!F:F, "Barang Datang") + SUMIFS(Transaksi!K:K, Transaksi!E:E, $C12, Transaksi!F:F, "Retur penjualan")+SUMIFS(Transaksi!K:K, Transaksi!E:E, $C12, Transaksi!F:F,"Rusak Internal") -> 0 | G12: =SUMIFS(Transaksi!I:I, Transaksi!E:E, $C12, Transaksi!F:F, "Terjual") + SUMIFS(Transaksi!J:J, Transaksi!E:E, $C12, Transaksi!F:F, "Retur Pembelian")+SUMIFS(Transaksi!I:I, Transaksi!E:E, $C12, Transaksi!F:F, "Dipakai Sendiri") -> 0 | H12: =IF(or(D12<>"",AND(B12<>"",C12<>"")),D12+E12-F12-G12,"") -> 29 | I12: =if(AND(H12<>"",J12<>""), H12*J12,"") | K12: 20000
A13: =IF(B13<>"",ROW(B13)-ROW($B$1),"") -> 12 | B13: OBENG 16-25 | C13: 003D/OBENG-16-25 | D13: 11 | E13: =SUMIFS(Transaksi!J:J, Transaksi!E:E, $C13, Transaksi!F:F, "Barang Datang")+SUMIFS(Transaksi!J:J, Transaksi!E:E,$C13,Transaksi!F:F,"Retur Penjualan") -> 0 | F13: =SUMIFS(Transaksi!K:K, Transaksi!E:E, $C13, Transaksi!F:F, "Barang Datang") + SUMIFS(Transaksi!K:K, Transaksi!E:E, $C13, Transaksi!F:F, "Retur penjualan")+SUMIFS(Transaksi!K:K, Transaksi!E:E, $C13, Transaksi!F:F,"Rusak Internal") -> 0 | G13: =SUMIFS(Transaksi!I:I, Transaksi!E:E, $C13, Transaksi!F:F, "Terjual") + SUMIFS(Transaksi!J:J, Transaksi!E:E, $C13, Transaksi!F:F, "Retur Pembelian")+SUMIFS(Transaksi!I:I, Transaksi!E:E, $C13, Transaksi!F:F, "Dipakai Sendiri") -> 0 | H13: =IF(or(D13<>"",AND(B13<>"",C13<>"")),D13+E13-F13-G13,"") -> 11 | I13: =if(AND(H13<>"",J13<>""), H13*J13,"") | K13: 10000
... A253: =IF(B253<>"",ROW(B253)-ROW($B$1),"") -> 252 | B253: STOP TUNGGAL MERAH | C253: STOPTUNGGAL-MERAH | D253: 62 | E253: =SUMIFS(Transaksi!J:J, Transaksi!E:E, $C253, Transaksi!F:F, "Barang Datang")+SUMIFS(Transaksi!J:J, Transaksi!E:E,$C253,Transaksi!F:F,"Retur Penjualan") -> 0 | F253: =SUMIFS(Transaksi!K:K, Transaksi!E:E, $C253, Transaksi!F:F, "Barang Datang") + SUMIFS(Transaksi!K:K, Transaksi!E:E, $C253, Transaksi!F:F, "Retur penjualan")+SUMIFS(Transaksi!K:K, Transaksi!E:E, $C253, Transaksi!F:F,"Rusak Internal") -> 0 | G253: =SUMIFS(Transaksi!I:I, Transaksi!E:E, $C253, Transaksi!F:F, "Terjual") + SUMIFS(Transaksi!J:J, Transaksi!E:E, $C253, Transaksi!F:F, "Retur Pembelian")+SUMIFS(Transaksi!I:I, Transaksi!E:E, $C253, Transaksi!F:F, "Dipakai Sendiri") -> 0 | H253: =IF(or(D253<>"",AND(B253<>"",C253<>"")),D253+E253-F253-G253,"") -> 62 | I253: =if(AND(H253<>"",J253<>""), H253*J253,"") | K253: 40000
